[2025-02-01T20:21:01.108+0000] {local_task_job_runner.py:120} INFO - ::group::Pre task execution logs
[2025-02-01T20:21:01.144+0000] {taskinstance.py:2073} INFO - Dependencies all met for dep_context=non-requeueable deps ti=<TaskInstance: DATABRICKS_DAG.run_now manual__2025-02-01T20:20:52.785531+00:00 [queued]>
[2025-02-01T20:21:01.163+0000] {taskinstance.py:2073} INFO - Dependencies all met for dep_context=requeueable deps ti=<TaskInstance: DATABRICKS_DAG.run_now manual__2025-02-01T20:20:52.785531+00:00 [queued]>
[2025-02-01T20:21:01.165+0000] {taskinstance.py:2303} INFO - Starting attempt 1 of 2
[2025-02-01T20:21:01.196+0000] {taskinstance.py:2327} INFO - Executing <Task(DatabricksRunNowOperator): run_now> on 2025-02-01 20:20:52.785531+00:00
[2025-02-01T20:21:01.212+0000] {warnings.py:110} WARNING - /home/***/.local/lib/python3.12/site-packages/***/task/task_runner/standard_task_runner.py:61: DeprecationWarning: This process (pid=321) is multi-threaded, use of fork() may lead to deadlocks in the child.
  pid = os.fork()

[2025-02-01T20:21:01.215+0000] {standard_task_runner.py:63} INFO - Started process 323 to run task
[2025-02-01T20:21:01.215+0000] {standard_task_runner.py:90} INFO - Running: ['***', 'tasks', 'run', 'DATABRICKS_DAG', 'run_now', 'manual__2025-02-01T20:20:52.785531+00:00', '--job-id', '203', '--raw', '--subdir', 'DAGS_FOLDER/dag_databricks.py', '--cfg-path', '/tmp/tmphc208l72']
[2025-02-01T20:21:01.224+0000] {standard_task_runner.py:91} INFO - Job 203: Subtask run_now
[2025-02-01T20:21:01.351+0000] {task_command.py:426} INFO - Running <TaskInstance: DATABRICKS_DAG.run_now manual__2025-02-01T20:20:52.785531+00:00 [running]> on host 2892ee60bb8a
[2025-02-01T20:21:01.590+0000] {taskinstance.py:2644} INFO - Exporting env vars: AIRFLOW_CTX_DAG_OWNER='Andres Urrea' AIRFLOW_CTX_DAG_ID='DATABRICKS_DAG' AIRFLOW_CTX_TASK_ID='run_now' AIRFLOW_CTX_EXECUTION_DATE='2025-02-01T20:20:52.785531+00:00' AIRFLOW_CTX_TRY_NUMBER='1' AIRFLOW_CTX_DAG_RUN_ID='manual__2025-02-01T20:20:52.785531+00:00'
[2025-02-01T20:21:01.597+0000] {taskinstance.py:430} INFO - ::endgroup::
[2025-02-01T20:21:01.616+0000] {base.py:84} INFO - Using connection ID 'Databricks-connection-***' for task execution.
[2025-02-01T20:21:03.229+0000] {databricks.py:65} INFO - Run submitted with run_id: 602468044203974
[2025-02-01T20:21:04.598+0000] {databricks.py:127} INFO - run_now in run state: {'life_cycle_state': 'RUNNING', 'result_state': '', 'state_message': ''}
[2025-02-01T20:21:04.600+0000] {databricks.py:128} INFO - View run status, Spark UI, and logs at https://adb-3338530560336691.11.azuredatabricks.net/?o=3338530560336691#job/882479244738536/run/602468044203974
[2025-02-01T20:21:04.602+0000] {databricks.py:129} INFO - Sleeping for 30 seconds.
[2025-02-01T20:21:36.420+0000] {taskinstance.py:441} INFO - ::group::Post task execution logs
[2025-02-01T20:21:36.451+0000] {taskinstance.py:2890} ERROR - Task failed with exception
Traceback (most recent call last):
  File "/home/airflow/.local/lib/python3.12/site-packages/airflow/models/taskinstance.py", line 465, in _execute_task
    result = _execute_callable(context=context, **execute_callable_kwargs)
             ^^^^^^^^^^^^^^^^^^^^^^^^^^^^^^^^^^^^^^^^^^^^^^^^^^^^^^^^^^^^^
  File "/home/airflow/.local/lib/python3.12/site-packages/airflow/models/taskinstance.py", line 432, in _execute_callable
    return execute_callable(context=context, **execute_callable_kwargs)
           ^^^^^^^^^^^^^^^^^^^^^^^^^^^^^^^^^^^^^^^^^^^^^^^^^^^^^^^^^^^^
  File "/home/airflow/.local/lib/python3.12/site-packages/airflow/models/baseoperator.py", line 400, in wrapper
    return func(self, *args, **kwargs)
           ^^^^^^^^^^^^^^^^^^^^^^^^^^^
  File "/home/airflow/.local/lib/python3.12/site-packages/airflow/providers/databricks/operators/databricks.py", line 929, in execute
    _handle_databricks_operator_execution(self, hook, self.log, context)
  File "/home/airflow/.local/lib/python3.12/site-packages/airflow/providers/databricks/operators/databricks.py", line 125, in _handle_databricks_operator_execution
    raise AirflowException(error_message)
airflow.exceptions.AirflowException: run_now failed with terminal state: {'life_cycle_state': 'INTERNAL_ERROR', 'result_state': 'FAILED', 'state_message': 'Task job_test_*** failed with message: Workload failed, see run output for details. This caused all downstream tasks to get skipped.'} and with the errors [{'task_key': 'job_test_***', 'run_id': 141155228944307, 'error': "OSError: [E050] Can't find model 'en_core_web_sm'. It doesn't seem to be a Python package or a valid path to a data directory."}]
[2025-02-01T20:21:36.469+0000] {taskinstance.py:1205} INFO - Marking task as UP_FOR_RETRY. dag_id=DATABRICKS_DAG, task_id=run_now, execution_date=20250201T202052, start_date=20250201T202101, end_date=20250201T202136
[2025-02-01T20:21:36.507+0000] {standard_task_runner.py:110} ERROR - Failed to execute job 203 for task run_now (run_now failed with terminal state: {'life_cycle_state': 'INTERNAL_ERROR', 'result_state': 'FAILED', 'state_message': 'Task job_test_*** failed with message: Workload failed, see run output for details. This caused all downstream tasks to get skipped.'} and with the errors [{'task_key': 'job_test_***', 'run_id': 141155228944307, 'error': "OSError: [E050] Can't find model 'en_core_web_sm'. It doesn't seem to be a Python package or a valid path to a data directory."}]; 323)
[2025-02-01T20:21:36.571+0000] {local_task_job_runner.py:240} INFO - Task exited with return code 1
[2025-02-01T20:21:36.628+0000] {taskinstance.py:3482} INFO - 0 downstream tasks scheduled from follow-on schedule check
[2025-02-01T20:21:36.633+0000] {local_task_job_runner.py:222} INFO - ::endgroup::
